2024-06-21 15:57:26,947 INFO    StreamThr :12944 [internal.py:wandb_internal():85] W&B internal server running at pid: 12944, started at: 2024-06-21 15:57:26.946153
2024-06-21 15:57:26,948 DEBUG   HandlerThread:12944 [handler.py:handle_request():158] handle_request: status
2024-06-21 15:57:26,953 INFO    WriterThread:12944 [datastore.py:open_for_write():87] open: F:\mycode\pykan\wandb\run-20240621_155726-2n20rz4o\run-2n20rz4o.wandb
2024-06-21 15:57:26,953 DEBUG   SenderThread:12944 [sender.py:send():379] send: header
2024-06-21 15:57:27,062 DEBUG   SenderThread:12944 [sender.py:send():379] send: run
2024-06-21 15:57:28,121 ERROR   SenderThread:12944 [internal_api.py:execute():344] 403 response executing GraphQL.
2024-06-21 15:57:28,121 ERROR   SenderThread:12944 [internal_api.py:execute():345] {"errors":[{"message":"permission denied","path":["upsertBucket"],"extensions":{"code":"PERMISSION_ERROR"}}],"data":{"upsertBucket":null}}
2024-06-21 15:57:28,124 ERROR   SenderThread:12944 [sender.py:send_run():1009] It appears that you do not have permission to access the requested resource. Please reach out to the project owner to grant you access. If you have the correct permissions, verify that there are no issues with your networking setup.(Error 403: Forbidden)
Traceback (most recent call last):
  File "F:\mycode\pykan\kannet\Lib\site-packages\wandb\sdk\lib\retry.py", line 131, in __call__
    result = self._call_fn(*args, **kwargs)
             ^^^^^^^^^^^^^^^^^^^^^^^^^^^^^^
  File "F:\mycode\pykan\kannet\Lib\site-packages\wandb\sdk\internal\internal_api.py", line 340, in execute
    return self.client.execute(*args, **kwargs)  # type: ignore
           ^^^^^^^^^^^^^^^^^^^^^^^^^^^^^^^^^^^^
  File "F:\mycode\pykan\kannet\Lib\site-packages\wandb\vendor\gql-0.2.0\wandb_gql\client.py", line 52, in execute
    result = self._get_result(document, *args, **kwargs)
             ^^^^^^^^^^^^^^^^^^^^^^^^^^^^^^^^^^^^^^^^^^^
  File "F:\mycode\pykan\kannet\Lib\site-packages\wandb\vendor\gql-0.2.0\wandb_gql\client.py", line 60, in _get_result
    return self.transport.execute(document, *args, **kwargs)
           ^^^^^^^^^^^^^^^^^^^^^^^^^^^^^^^^^^^^^^^^^^^^^^^^^
  File "F:\mycode\pykan\kannet\Lib\site-packages\wandb\sdk\lib\gql_request.py", line 59, in execute
    request.raise_for_status()
  File "F:\mycode\pykan\kannet\Lib\site-packages\requests\models.py", line 1024, in raise_for_status
    raise HTTPError(http_error_msg, response=self)
requests.exceptions.HTTPError: 403 Client Error: Forbidden for url: https://api.wandb.ai/graphql

During handling of the above exception, another exception occurred:

Traceback (most recent call last):
  File "F:\mycode\pykan\kannet\Lib\site-packages\wandb\sdk\internal\sender.py", line 1007, in send_run
    server_run = self._init_run(run, config_value_dict)
                 ^^^^^^^^^^^^^^^^^^^^^^^^^^^^^^^^^^^^^^
  File "F:\mycode\pykan\kannet\Lib\site-packages\wandb\sdk\internal\sender.py", line 1079, in _init_run
    server_run, inserted, server_messages = self._api.upsert_run(
                                            ^^^^^^^^^^^^^^^^^^^^^
  File "F:\mycode\pykan\kannet\Lib\site-packages\wandb\apis\normalize.py", line 73, in wrapper
    raise err
  File "F:\mycode\pykan\kannet\Lib\site-packages\wandb\apis\normalize.py", line 41, in wrapper
    return func(*args, **kwargs)
           ^^^^^^^^^^^^^^^^^^^^^
  File "F:\mycode\pykan\kannet\Lib\site-packages\wandb\sdk\internal\internal_api.py", line 2190, in upsert_run
    response = self.gql(
               ^^^^^^^^^
  File "F:\mycode\pykan\kannet\Lib\site-packages\wandb\sdk\internal\internal_api.py", line 312, in gql
    ret = self._retry_gql(
          ^^^^^^^^^^^^^^^^
  File "F:\mycode\pykan\kannet\Lib\site-packages\wandb\sdk\lib\retry.py", line 147, in __call__
    retry_timedelta_triggered = check_retry_fn(e)
                                ^^^^^^^^^^^^^^^^^
  File "F:\mycode\pykan\kannet\Lib\site-packages\wandb\util.py", line 968, in check_retry_fn
    return fallback_retry_fn(e)
           ^^^^^^^^^^^^^^^^^^^^
  File "F:\mycode\pykan\kannet\Lib\site-packages\wandb\util.py", line 910, in no_retry_auth
    raise CommError(
wandb.errors.CommError: It appears that you do not have permission to access the requested resource. Please reach out to the project owner to grant you access. If you have the correct permissions, verify that there are no issues with your networking setup.(Error 403: Forbidden)
2024-06-21 15:57:28,917 DEBUG   HandlerThread:12944 [handler.py:handle_request():158] handle_request: shutdown
2024-06-21 15:57:28,917 INFO    HandlerThread:12944 [handler.py:finish():882] shutting down handler
2024-06-21 15:57:29,077 INFO    WriterThread:12944 [datastore.py:close():296] close: F:\mycode\pykan\wandb\run-20240621_155726-2n20rz4o\run-2n20rz4o.wandb
2024-06-21 15:57:29,140 INFO    SenderThread:12944 [sender.py:finish():1608] shutting down sender
